[2024-06-04 17:15:06,723][flwr][INFO] - Starting Flower simulation, config: num_rounds=1, no round_timeout
[2024-06-04 17:15:13,010][flwr][INFO] - Flower VCE: Ray initialized with resources: {'node:127.0.0.1': 1.0, 'memory': 3114312500.0, 'object_store_memory': 1557156249.0, 'node:__internal_head__': 1.0, 'CPU': 4.0, 'GPU': 1.0, 'accelerator_type:G': 1.0}
[2024-06-04 17:15:13,010][flwr][INFO] - Optimize your simulation with Flower VCE: https://flower.ai/docs/framework/how-to-run-simulations.html
[2024-06-04 17:15:13,010][flwr][INFO] - Flower VCE: Resources for each Virtual Client: {'num_cpus': 2, 'num_gpus': 1.0}
[2024-06-04 17:15:13,043][flwr][INFO] - Flower VCE: Creating VirtualClientEngineActorPool with 1 actors
[2024-06-04 17:15:13,046][flwr][INFO] - [INIT]
[2024-06-04 17:15:13,046][flwr][INFO] - Requesting initial parameters from one random client
[2024-06-04 17:15:18,651][flwr][ERROR] - Traceback (most recent call last):
  File "C:\Users\user\anaconda3\envs\pytorch_cuda\lib\site-packages\flwr\simulation\ray_transport\ray_client_proxy.py", line 73, in _submit_job
    out_mssg, updated_context = self.actor_pool.get_client_result(
  File "C:\Users\user\anaconda3\envs\pytorch_cuda\lib\site-packages\flwr\simulation\ray_transport\ray_actor.py", line 399, in get_client_result
    return self._fetch_future_result(cid)
  File "C:\Users\user\anaconda3\envs\pytorch_cuda\lib\site-packages\flwr\simulation\ray_transport\ray_actor.py", line 280, in _fetch_future_result
    res_cid, out_mssg, updated_context = ray.get(
  File "C:\Users\user\anaconda3\envs\pytorch_cuda\lib\site-packages\ray\_private\auto_init_hook.py", line 21, in auto_init_wrapper
    return fn(*args, **kwargs)
  File "C:\Users\user\anaconda3\envs\pytorch_cuda\lib\site-packages\ray\_private\client_mode_hook.py", line 103, in wrapper
    return func(*args, **kwargs)
  File "C:\Users\user\anaconda3\envs\pytorch_cuda\lib\site-packages\ray\_private\worker.py", line 2667, in get
    values, debugger_breakpoint = worker.get_objects(object_refs, timeout=timeout)
  File "C:\Users\user\anaconda3\envs\pytorch_cuda\lib\site-packages\ray\_private\worker.py", line 864, in get_objects
    raise value.as_instanceof_cause()
ray.exceptions.RayTaskError(ClientAppException): [36mray::ClientAppActor.run()[39m (pid=13168, ip=127.0.0.1, actor_id=a5ba73a5d77148cb86b61a0f01000000, repr=<flwr.simulation.ray_transport.ray_actor.ClientAppActor object at 0x000001A3F0AEE8B0>)
  File "C:\Users\user\anaconda3\envs\pytorch_cuda\lib\site-packages\flwr\client\client_app.py", line 98, in __call__
    return self._call(message, context)
  File "C:\Users\user\anaconda3\envs\pytorch_cuda\lib\site-packages\flwr\client\client_app.py", line 81, in ffn
    out_message = handle_legacy_message_from_msgtype(
  File "C:\Users\user\anaconda3\envs\pytorch_cuda\lib\site-packages\flwr\client\message_handler\message_handler.py", line 96, in handle_legacy_message_from_msgtype
    client = client_fn(str(message.metadata.partition_id))
  File "G:\BACHELOR_PROJECT\FL\flower_simulation\client.py", line 100, in client_fn
    return FlowerClient(
TypeError: __init__() got an unexpected keyword argument 'vallodaer'

The above exception was the direct cause of the following exception:

[36mray::ClientAppActor.run()[39m (pid=13168, ip=127.0.0.1, actor_id=a5ba73a5d77148cb86b61a0f01000000, repr=<flwr.simulation.ray_transport.ray_actor.ClientAppActor object at 0x000001A3F0AEE8B0>)
  File "python\ray\_raylet.pyx", line 1883, in ray._raylet.execute_task
  File "python\ray\_raylet.pyx", line 1984, in ray._raylet.execute_task
  File "python\ray\_raylet.pyx", line 1889, in ray._raylet.execute_task
  File "python\ray\_raylet.pyx", line 1830, in ray._raylet.execute_task.function_executor
  File "C:\Users\user\anaconda3\envs\pytorch_cuda\lib\site-packages\ray\_private\function_manager.py", line 724, in actor_method_executor
    return method(__ray_actor, *args, **kwargs)
  File "C:\Users\user\anaconda3\envs\pytorch_cuda\lib\site-packages\ray\util\tracing\tracing_helper.py", line 467, in _resume_span
    return method(self, *_args, **_kwargs)
  File "C:\Users\user\anaconda3\envs\pytorch_cuda\lib\site-packages\flwr\simulation\ray_transport\ray_actor.py", line 64, in run
    raise ClientAppException(str(ex)) from ex
flwr.client.client_app.ClientAppException: 
Exception ClientAppException occurred. Message: __init__() got an unexpected keyword argument 'vallodaer'

[2024-06-04 17:15:18,666][flwr][ERROR] - [36mray::ClientAppActor.run()[39m (pid=13168, ip=127.0.0.1, actor_id=a5ba73a5d77148cb86b61a0f01000000, repr=<flwr.simulation.ray_transport.ray_actor.ClientAppActor object at 0x000001A3F0AEE8B0>)
  File "C:\Users\user\anaconda3\envs\pytorch_cuda\lib\site-packages\flwr\client\client_app.py", line 98, in __call__
    return self._call(message, context)
  File "C:\Users\user\anaconda3\envs\pytorch_cuda\lib\site-packages\flwr\client\client_app.py", line 81, in ffn
    out_message = handle_legacy_message_from_msgtype(
  File "C:\Users\user\anaconda3\envs\pytorch_cuda\lib\site-packages\flwr\client\message_handler\message_handler.py", line 96, in handle_legacy_message_from_msgtype
    client = client_fn(str(message.metadata.partition_id))
  File "G:\BACHELOR_PROJECT\FL\flower_simulation\client.py", line 100, in client_fn
    return FlowerClient(
TypeError: __init__() got an unexpected keyword argument 'vallodaer'

The above exception was the direct cause of the following exception:

[36mray::ClientAppActor.run()[39m (pid=13168, ip=127.0.0.1, actor_id=a5ba73a5d77148cb86b61a0f01000000, repr=<flwr.simulation.ray_transport.ray_actor.ClientAppActor object at 0x000001A3F0AEE8B0>)
  File "python\ray\_raylet.pyx", line 1883, in ray._raylet.execute_task
  File "python\ray\_raylet.pyx", line 1984, in ray._raylet.execute_task
  File "python\ray\_raylet.pyx", line 1889, in ray._raylet.execute_task
  File "python\ray\_raylet.pyx", line 1830, in ray._raylet.execute_task.function_executor
  File "C:\Users\user\anaconda3\envs\pytorch_cuda\lib\site-packages\ray\_private\function_manager.py", line 724, in actor_method_executor
    return method(__ray_actor, *args, **kwargs)
  File "C:\Users\user\anaconda3\envs\pytorch_cuda\lib\site-packages\ray\util\tracing\tracing_helper.py", line 467, in _resume_span
    return method(self, *_args, **_kwargs)
  File "C:\Users\user\anaconda3\envs\pytorch_cuda\lib\site-packages\flwr\simulation\ray_transport\ray_actor.py", line 64, in run
    raise ClientAppException(str(ex)) from ex
flwr.client.client_app.ClientAppException: 
Exception ClientAppException occurred. Message: __init__() got an unexpected keyword argument 'vallodaer'
[2024-06-04 17:15:18,681][flwr][ERROR] - [36mray::ClientAppActor.run()[39m (pid=13168, ip=127.0.0.1, actor_id=a5ba73a5d77148cb86b61a0f01000000, repr=<flwr.simulation.ray_transport.ray_actor.ClientAppActor object at 0x000001A3F0AEE8B0>)
  File "C:\Users\user\anaconda3\envs\pytorch_cuda\lib\site-packages\flwr\client\client_app.py", line 98, in __call__
    return self._call(message, context)
  File "C:\Users\user\anaconda3\envs\pytorch_cuda\lib\site-packages\flwr\client\client_app.py", line 81, in ffn
    out_message = handle_legacy_message_from_msgtype(
  File "C:\Users\user\anaconda3\envs\pytorch_cuda\lib\site-packages\flwr\client\message_handler\message_handler.py", line 96, in handle_legacy_message_from_msgtype
    client = client_fn(str(message.metadata.partition_id))
  File "G:\BACHELOR_PROJECT\FL\flower_simulation\client.py", line 100, in client_fn
    return FlowerClient(
TypeError: __init__() got an unexpected keyword argument 'vallodaer'

The above exception was the direct cause of the following exception:

[36mray::ClientAppActor.run()[39m (pid=13168, ip=127.0.0.1, actor_id=a5ba73a5d77148cb86b61a0f01000000, repr=<flwr.simulation.ray_transport.ray_actor.ClientAppActor object at 0x000001A3F0AEE8B0>)
  File "python\ray\_raylet.pyx", line 1883, in ray._raylet.execute_task
  File "python\ray\_raylet.pyx", line 1984, in ray._raylet.execute_task
  File "python\ray\_raylet.pyx", line 1889, in ray._raylet.execute_task
  File "python\ray\_raylet.pyx", line 1830, in ray._raylet.execute_task.function_executor
  File "C:\Users\user\anaconda3\envs\pytorch_cuda\lib\site-packages\ray\_private\function_manager.py", line 724, in actor_method_executor
    return method(__ray_actor, *args, **kwargs)
  File "C:\Users\user\anaconda3\envs\pytorch_cuda\lib\site-packages\ray\util\tracing\tracing_helper.py", line 467, in _resume_span
    return method(self, *_args, **_kwargs)
  File "C:\Users\user\anaconda3\envs\pytorch_cuda\lib\site-packages\flwr\simulation\ray_transport\ray_actor.py", line 64, in run
    raise ClientAppException(str(ex)) from ex
flwr.client.client_app.ClientAppException: 
Exception ClientAppException occurred. Message: __init__() got an unexpected keyword argument 'vallodaer'
[2024-06-04 17:15:18,691][flwr][ERROR] - Traceback (most recent call last):
  File "C:\Users\user\anaconda3\envs\pytorch_cuda\lib\site-packages\flwr\simulation\app.py", line 308, in start_simulation
    hist = run_fl(
  File "C:\Users\user\anaconda3\envs\pytorch_cuda\lib\site-packages\flwr\server\server.py", line 483, in run_fl
    hist, elapsed_time = server.fit(
  File "C:\Users\user\anaconda3\envs\pytorch_cuda\lib\site-packages\flwr\server\server.py", line 93, in fit
    self.parameters = self._get_initial_parameters(server_round=0, timeout=timeout)
  File "C:\Users\user\anaconda3\envs\pytorch_cuda\lib\site-packages\flwr\server\server.py", line 282, in _get_initial_parameters
    get_parameters_res = random_client.get_parameters(
  File "C:\Users\user\anaconda3\envs\pytorch_cuda\lib\site-packages\flwr\simulation\ray_transport\ray_client_proxy.py", line 148, in get_parameters
    message_out = self._submit_job(message, timeout)
  File "C:\Users\user\anaconda3\envs\pytorch_cuda\lib\site-packages\flwr\simulation\ray_transport\ray_client_proxy.py", line 87, in _submit_job
    raise ex
  File "C:\Users\user\anaconda3\envs\pytorch_cuda\lib\site-packages\flwr\simulation\ray_transport\ray_client_proxy.py", line 73, in _submit_job
    out_mssg, updated_context = self.actor_pool.get_client_result(
  File "C:\Users\user\anaconda3\envs\pytorch_cuda\lib\site-packages\flwr\simulation\ray_transport\ray_actor.py", line 399, in get_client_result
    return self._fetch_future_result(cid)
  File "C:\Users\user\anaconda3\envs\pytorch_cuda\lib\site-packages\flwr\simulation\ray_transport\ray_actor.py", line 280, in _fetch_future_result
    res_cid, out_mssg, updated_context = ray.get(
  File "C:\Users\user\anaconda3\envs\pytorch_cuda\lib\site-packages\ray\_private\auto_init_hook.py", line 21, in auto_init_wrapper
    return fn(*args, **kwargs)
  File "C:\Users\user\anaconda3\envs\pytorch_cuda\lib\site-packages\ray\_private\client_mode_hook.py", line 103, in wrapper
    return func(*args, **kwargs)
  File "C:\Users\user\anaconda3\envs\pytorch_cuda\lib\site-packages\ray\_private\worker.py", line 2667, in get
    values, debugger_breakpoint = worker.get_objects(object_refs, timeout=timeout)
  File "C:\Users\user\anaconda3\envs\pytorch_cuda\lib\site-packages\ray\_private\worker.py", line 864, in get_objects
    raise value.as_instanceof_cause()
ray.exceptions.RayTaskError(ClientAppException): [36mray::ClientAppActor.run()[39m (pid=13168, ip=127.0.0.1, actor_id=a5ba73a5d77148cb86b61a0f01000000, repr=<flwr.simulation.ray_transport.ray_actor.ClientAppActor object at 0x000001A3F0AEE8B0>)
  File "C:\Users\user\anaconda3\envs\pytorch_cuda\lib\site-packages\flwr\client\client_app.py", line 98, in __call__
    return self._call(message, context)
  File "C:\Users\user\anaconda3\envs\pytorch_cuda\lib\site-packages\flwr\client\client_app.py", line 81, in ffn
    out_message = handle_legacy_message_from_msgtype(
  File "C:\Users\user\anaconda3\envs\pytorch_cuda\lib\site-packages\flwr\client\message_handler\message_handler.py", line 96, in handle_legacy_message_from_msgtype
    client = client_fn(str(message.metadata.partition_id))
  File "G:\BACHELOR_PROJECT\FL\flower_simulation\client.py", line 100, in client_fn
    return FlowerClient(
TypeError: __init__() got an unexpected keyword argument 'vallodaer'

The above exception was the direct cause of the following exception:

[36mray::ClientAppActor.run()[39m (pid=13168, ip=127.0.0.1, actor_id=a5ba73a5d77148cb86b61a0f01000000, repr=<flwr.simulation.ray_transport.ray_actor.ClientAppActor object at 0x000001A3F0AEE8B0>)
  File "python\ray\_raylet.pyx", line 1883, in ray._raylet.execute_task
  File "python\ray\_raylet.pyx", line 1984, in ray._raylet.execute_task
  File "python\ray\_raylet.pyx", line 1889, in ray._raylet.execute_task
  File "python\ray\_raylet.pyx", line 1830, in ray._raylet.execute_task.function_executor
  File "C:\Users\user\anaconda3\envs\pytorch_cuda\lib\site-packages\ray\_private\function_manager.py", line 724, in actor_method_executor
    return method(__ray_actor, *args, **kwargs)
  File "C:\Users\user\anaconda3\envs\pytorch_cuda\lib\site-packages\ray\util\tracing\tracing_helper.py", line 467, in _resume_span
    return method(self, *_args, **_kwargs)
  File "C:\Users\user\anaconda3\envs\pytorch_cuda\lib\site-packages\flwr\simulation\ray_transport\ray_actor.py", line 64, in run
    raise ClientAppException(str(ex)) from ex
flwr.client.client_app.ClientAppException: 
Exception ClientAppException occurred. Message: __init__() got an unexpected keyword argument 'vallodaer'

[2024-06-04 17:15:18,718][flwr][ERROR] - Your simulation crashed :(. This could be because of several reasons. The most common are: 
	 > Sometimes, issues in the simulation code itself can cause crashes. It's always a good idea to double-check your code for any potential bugs or inconsistencies that might be contributing to the problem. For example: 
		 - You might be using a class attribute in your clients that hasn't been defined.
		 - There could be an incorrect method call to a 3rd party library (e.g., PyTorch).
		 - The return types of methods in your clients/strategies might be incorrect.
	 > Your system couldn't fit a single VirtualClient: try lowering `client_resources`.
	 > All the actors in your pool crashed. This could be because: 
		 - You clients hit an out-of-memory (OOM) error and actors couldn't recover from it. Try launching your simulation with more generous `client_resources` setting (i.e. it seems {'num_cpus': 2, 'num_gpus': 1.0} is not enough for your run). Use fewer concurrent actors. 
		 - You were running a multi-node simulation and all worker nodes disconnected. The head node might still be alive but cannot accommodate any actor with resources: {'num_cpus': 2, 'num_gpus': 1.0}.
Take a look at the Flower simulation examples for guidance <https://flower.ai/docs/framework/how-to-run-simulations.html>.
